Workbook

Sheet Dashboard
A1: AI Engineering Lab, 24-Week AI Engineering Program
A2: Find the Signal. Act with Intelligence. · by Zorost Intelligence (https://zorost.com)
B4: Learner name | C4: Marko | D4: Start date | E4: 15.Sept.2026
B5: Program start | D5: Target end (24 weeks later)
A7: Week | B7: Section | C7: Title | D7: Status | E7: % Complete
A8: Week 01 | B8: Foundations | C8: Python Foundations & the AI Engineering Landscape | D8: =IF('Week 01'!$B$13>=1,"✅ Complete",IF('Week 01'!$B$13>0,"▶ In progress","☐ Not started")) -> ▶ In progress | E8: ='Week 01'!$B$13 -> 0.14285714
A9: Week 02 | B9: Foundations | C9: Data Engineering & SQL for AI | D9: =IF('Week 02'!$B$13>=1,"✅ Complete",IF('Week 02'!$B$13>0,"▶ In progress","☐ Not started")) -> ☐ Not started | E9: ='Week 02'!$B$13 -> 0
A10: Week 03 | B10: Foundations | C10: Machine Learning Fundamentals | D10: =IF('Week 03'!$B$13>=1,"✅ Complete",IF('Week 03'!$B$13>0,"▶ In progress","☐ Not started")) -> ☐ Not started | E10: ='Week 03'!$B$13 -> 0
A11: Week 04 | B11: Foundations | C11: Deep Learning with PyTorch | D11: =IF('Week 04'!$B$13>=1,"✅ Complete",IF('Week 04'!$B$13>0,"▶ In progress","☐ Not started")) -> ☐ Not started | E11: ='Week 04'!$B$13 -> 0
A12: Week 05 | B12: LLM Core | C12: How LLMs Work: Tokens to Transformers | D12: =IF('Week 05'!$B$13>=1,"✅ Complete",IF('Week 05'!$B$13>0,"▶ In progress","☐ Not started")) -> ☐ Not started | E12: ='Week 05'!$B$13 -> 0
A13: Week 06 | B13: LLM Core | C13: Prompt Engineering & the Context Window | D13: =IF('Week 06'!$B$13>=1,"✅ Complete",IF('Week 06'!$B$13>0,"▶ In progress","☐ Not started")) -> ☐ Not started | E13: ='Week 06'!$B$13 -> 0
A14: Week 07 | B14: LLM Core | C14: RAG, Vector Search & Knowledge Graphs | D14: =IF('Week 07'!$B$13>=1,"✅ Complete",IF('Week 07'!$B$13>0,"▶ In progress","☐ Not started")) -> ☐ Not started | E14: ='Week 07'!$B$13 -> 0
A15: Week 08 | B15: LLM Core | C15: Open Models & Local Inference: GPUs, Ollama, llama.cpp | D15: =IF('Week 08'!$B$13>=1,"✅ Complete",IF('Week 08'!$B$13>0,"▶ In progress","☐ Not started")) -> ☐ Not started | E15: ='Week 08'!$B$13 -> 0
A16: Week 09 | B16: Model Engineering | C16: Quantization & Efficient Inference | D16: =IF('Week 09'!$B$13>=1,"✅ Complete",IF('Week 09'!$B$13>0,"▶ In progress","☐ Not started")) -> ☐ Not started | E16: ='Week 09'!$B$13 -> 0
A17: Week 10 | B17: Model Engineering | C17: Fine-Tuning: LoRA, SFT & DPO | D17: =IF('Week 10'!$B$13>=1,"✅ Complete",IF('Week 10'!$B$13>0,"▶ In progress","☐ Not started")) -> ☐ Not started | E17: ='Week 10'!$B$13 -> 0
A18: Week 11 | B18: Model Engineering | C18: Evals & Error Analysis for AI Systems | D18: =IF('Week 11'!$B$13>=1,"✅ Complete",IF('Week 11'!$B$13>0,"▶ In progress","☐ Not started")) -> ☐ Not started | E18: ='Week 11'!$B$13 -> 0
A19: Week 12 | B19: Harnesses & Loops | C19: Coding-Agent Harnesses: Claude Code, Cursor, OpenCode, DSH | D19: =IF('Week 12'!$B$13>=1,"✅ Complete",IF('Week 12'!$B$13>0,"▶ In progress","☐ Not started")) -> ☐ Not started | E19: ='Week 12'!$B$13 -> 0
A20: Week 13 | B20: Harnesses & Loops | C20: Agentic Coding Loops & Spec-Driven Development | D20: =IF('Week 13'!$B$13>=1,"✅ Complete",IF('Week 13'!$B$13>0,"▶ In progress","☐ Not started")) -> ☐ Not started | E20: ='Week 13'!$B$13 -> 0
A21: Week 14 | B21: Agents | C21: Agent Fundamentals: The Loop, Tools & Memory | D21: =IF('Week 14'!$B$13>=1,"✅ Complete",IF('Week 14'!$B$13>0,"▶ In progress","☐ Not started")) -> ☐ Not started | E21: ='Week 14'!$B$13 -> 0
A22: Week 15 | B22: Agents | C22: Agent Frameworks: LangGraph & the State-Graph Model | D22: =IF('Week 15'!$B$13>=1,"✅ Complete",IF('Week 15'!$B$13>0,"▶ In progress","☐ Not started")) -> ☐ Not started | E22: ='Week 15'!$B$13 -> 0
A23: Week 16 | B23: Agents | C23: Multi-Agent Systems & MCP | D23: =IF('Week 16'!$B$13>=1,"✅ Complete",IF('Week 16'!$B$13>0,"▶ In progress","☐ Not started")) -> ☐ Not started | E23: ='Week 16'!$B$13 -> 0
A24: Week 17 | B24: Agents | C24: OpenClaw, Hermes & Agent Operations | D24: =IF('Week 17'!$B$13>=1,"✅ Complete",IF('Week 17'!$B$13>0,"▶ In progress","☐ Not started")) -> ☐ Not started | E24: ='Week 17'!$B$13 -> 0
A25: Week 18 | B25: Cloud AI Platforms | C25: Azure AI Foundry | D25: =IF('Week 18'!$B$13>=1,"✅ Complete",IF('Week 18'!$B$13>0,"▶ In progress","☐ Not started")) -> ☐ Not started | E25: ='Week 18'!$B$13 -> 0
A26: Week 19 | B26: Cloud AI Platforms | C26: Google Vertex AI & Gemini | D26: =IF('Week 19'!$B$13>=1,"✅ Complete",IF('Week 19'!$B$13>0,"▶ In progress","☐ Not started")) -> ☐ Not started | E26: ='Week 19'!$B$13 -> 0
A27: Week 20 | B27: Cloud AI Platforms | C27: AWS Bedrock & SageMaker AI | D27: =IF('Week 20'!$B$13>=1,"✅ Complete",IF('Week 20'!$B$13>0,"▶ In progress","☐ Not started")) -> ☐ Not started | E27: ='Week 20'!$B$13 -> 0
A28: Week 21 | B28: Databricks Zero to Hero | C28: Databricks Day Zero: Unity Catalog & the Lakehouse | D28: =IF('Week 21'!$B$13>=1,"✅ Complete",IF('Week 21'!$B$13>0,"▶ In progress","☐ Not started")) -> ☐ Not started | E28: ='Week 21'!$B$13 -> 0
A29: Week 22 | B29: Databricks Zero to Hero | C29: Databricks Data Engineering: PySpark, Streaming & Lakeflow | D29: =IF('Week 22'!$B$13>=1,"✅ Complete",IF('Week 22'!$B$13>0,"▶ In progress","☐ Not started")) -> ☐ Not started | E29: ='Week 22'!$B$13 -> 0
A30: Week 23 | B30: Databricks Zero to Hero | C30: Databricks ML & GenAI: Training, Serving, Genie | D30: =IF('Week 23'!$B$13>=1,"✅ Complete",IF('Week 23'!$B$13>0,"▶ In progress","☐ Not started")) -> ☐ Not started | E30: ='Week 23'!$B$13 -> 0
A31: Week 24 | B31: Databricks Zero to Hero | C31: Databricks Production: DABs, Governance & the Capstone | D31: =IF('Week 24'!$B$13>=1,"✅ Complete",IF('Week 24'!$B$13>0,"▶ In progress","☐ Not started")) -> ☐ Not started | E31: ='Week 24'!$B$13 -> 0
D33: Overall completion | E33: =AVERAGE(E8:E31) -> 0.005952381
A36: Phase summary
A37: Foundations | B37: Weeks 1 to 4 | C37: =AVERAGE(E8:E11) -> 0.035714286 | D37: Python, data engineering, classical ML, and deep learning, taught the AI engineering way: every model ships with a metric, a split, and an error analysis.
A38: LLM Core | B38: Weeks 5 to 8 | C38: =AVERAGE(E12:E15) -> 0 | D38: How LLMs actually work, from tokens and embeddings to attention and the KV cache, then the two engineering superpowers on top: prompt & context-window engineering, and retrieval (RAG + knowledge graphs). Week 8 goes fully local.
A39: Model Engineering | B39: Weeks 9 to 11 | C39: =AVERAGE(E16:E18) -> 0 | D39: Make models cheaper and yours: quantization formats and serving engines, fine-tuning with LoRA/SFT/DPO, and the discipline that decides it all, evals and error analysis.
A40: Harnesses & Loops | B40: Weeks 12 to 13 | C40: =AVERAGE(E19:E20) -> 0 | D40: Become dangerous with coding agents: Claude Code, Cursor, OpenCode, DeepSeek Harness, then run the three loops (agentic coding → developer feedback → external feedback) with a spec, a verifier, and a blast-radius rule.
A41: Agents | B41: Weeks 14 to 17 | C41: =AVERAGE(E21:E24) -> 0 | D41: From a hand-written ReAct loop to LangGraph state graphs, multi-agent orchestration, and MCP, then OpenClaw as a personal assistant and agent operations.
A42: Cloud AI Platforms | B42: Weeks 18 to 20 | C42: =AVERAGE(E25:E27) -> 0 | D42: The same ZoroLogistics support agent, deployed three ways: Azure AI Foundry (Microsoft), Vertex AI + AI Studio (Google), Bedrock + SageMaker (AWS). Compare capabilities, governance, and cost, then learn how to pick.
A43: Databricks Zero to Hero | B43: Weeks 21 to 24 | C43: =AVERAGE(E28:E31) -> 0 | D43: The full Zorost Databricks modernization playbook: Unity Catalog, Delta Lake medallion, DBSQL, PySpark, streaming, Lakeflow, MLflow, Mosaic AI, Genie, then DABs, CI/CD, governance, and FinOps, ending in the lakehouse capstone.
A45: Legend
A46: ☐ Not started | B46: not started yet
...

Sheet Week 01
A1: Week 01, Python Foundations & the AI Engineering Landscape
A2: Section: Foundations · Category: Python & Environment · ZoroLogistics case study
A3: 🎯 Use case: Generate the ZoroLogistics synthetic dataset (shipments, carriers, lanes) that every future week reuses.
A5: Day | B5: Task | C5: Status | D5: Notes
A6: Mon | B6: Set up VS Code, Python environment (uv or conda), and git; fork/clone the repo. | C6: ✅ Done | D6: 6
A7: Tue | B7: Complete the Python refresher exercises in the environment notebook. | C7: ☐ Not started
A8: Wed | B8: Run the environment check notebook end-to-end (versions, imports, deterministic seed). | C8: ☐ Not started
A9: Thu | B9: Build the ZoroLogistics data generator: shipments, carriers, lanes, deterministic seeds. | C9: ☐ Not started
A10: Fri | B10: Use case: generate the 100k-row dataset, save to CSV/Parquet, commit it with a data dictionary. | C10: ☐ Not started
A11: Sat | B11: Take the Week 1 quiz (quiz.md), pass with 8/10; record the score in Notes. | C11: ☐ Not started
A12: Milestone | B12: Update the Excel tracker: Week 1 checked off; push your fork to GitHub. | C12: ☐ Not started
A13: Week completion | B13: =COUNTIF(C6:C12,"✅ Done")/7 -> 0.14285714 | C13: =REPT("█",ROUND(B13*20,0))&REPT("░",20-ROUND(B13*20,0)) -> ███░░░░░░░░░░░░░░░░░ | E13: Deliverables: Working local environment (checklist notebook passes) · ZoroLogistics data generator (100k rows, seeded) · Data dictionary for the generated dataset

Sheet Week 02
A1: Week 02, Data Engineering & SQL for AI
A2: Section: Foundations · Category: Data & SQL · ZoroLogistics case study
A3: 🎯 Use case: Clean and profile the raw shipment dataset into an analytics-ready 'silver' table.
A5: Day | B5: Task | C5: Status | D5: Notes
A6: Mon | B6: Study data quality concepts; run the pandas refresher exercises. | C6: ☐ Not started
A7: Tue | B7: Run the pandas cleaning notebook; find and document 5 data issues in the generator output. | C7: ☐ Not started
A8: Wed | B8: Write SQL queries in DuckDB: on-time rate by carrier/lane/month, windows, top-lane analysis. | C8: ☐ Not started
A9: Thu | B9: Add a data validation suite (pandera) with at least 10 checks. | C9: ☐ Not started
A10: Fri | B10: Use case: deliver the cleaned silver dataset + profile report; document every cleaning decision. | C10: ☐ Not started
A11: Sat | B11: Take the Week 2 quiz (quiz.md), pass with 8/10; record the score in Notes. | C11: ☐ Not started
A12: Milestone | B12: Update the Excel tracker; commit the silver pipeline script. | C12: ☐ Not started
A13: Week completion | B13: =COUNTIF(C6:C12,"✅ Done")/7 -> 0 | C13: =REPT("█",ROUND(B13*20,0))&REPT("░",20-ROUND(B13*20,0)) -> ░░░░░░░░░░░░░░░░░░░░ | E13: Deliverables: Silver dataset + validation suite (10+ checks) · SQL analytics queries (on-time rate by carrier/lane/month) · Data profile report

Sheet Week 03
A1: Week 03, Machine Learning Fundamentals
A2: Section: Foundations · Category: Classical ML · ZoroLogistics case study
A3: 🎯 Use case: Baseline ETA (estimated time of arrival) regression and on-time classification from shipment features.
A5: Day | B5: Task | C5: Status | D5: Notes
A6: Mon | B6: Study supervised learning and the eval mindset: pick the metric before the model. | C6: ☐ Not started
A7: Tue | B7: Run the ETA regression baseline; log MAE/RMSE for 3 models in a comparison table. | C7: ☐ Not started
A8: Wed | B8: Implement a time-aware split and cross-validation; compare models fairly. | C8: ☐ Not started
A9: Thu | B9: On-time classification: precision/recall/F1, threshold tradeoff, confusion matrix. | C9: ☐ Not started
A10: Fri | B10: Use case: write the Week 3 model card (metric, split, top error source) and commit it. | C10: ☐ Not started
A11: Sat | B11: Take the Week 3 quiz (quiz.md), pass with 8/10; record the score in Notes. | C11: ☐ Not started
A12: Milestone | B12: Update the Excel tracker; log all experiments to a JSON experiment log. | C12: ☐ Not started
A13: Week completion | B13: =COUNTIF(C6:C12,"✅ Done")/7 -> 0 | C13: =REPT("█",ROUND(B13*20,0))&REPT("░",20-ROUND(B13*20,0)) -> ░░░░░░░░░░░░░░░░░░░░ | E13: Deliverables: ETA regression baseline with logged metrics · On-time classifier with threshold tradeoff analysis · Week 3 model card (metric, split, top error source)

Sheet Week 04
A1: Week 04, Deep Learning with PyTorch
A2: Section: Foundations · Category: Deep Learning · ZoroLogistics case study
A3: 🎯 Use case: A neural ETA model that beats the Week 3 baseline, with a first error analysis by carrier and lane.
A5: Day | B5: Task | C5: Status | D5: Notes
A6: Mon | B6: Study tensors, autograd, and the computation-graph mental model. | C6: ☐ Not started
A7: Tue | B7: Run the MLP notebook; verify loss curves; deliberately break one thing and diagnose it. | C7: ☐ Not started
A8: Wed | B8: Add dropout/weight decay; tune 3 hyperparameters using the validation split. | C8: ☐ Not started
A9: Thu | B9: Compare neural vs baseline on the test set; segment errors by carrier and lane. | C9: ☐ Not started
A10: Fri | B10: Use case: write the error-analysis note (biggest error cluster + hypothesis). | C10: ☐ Not started
A11: Sat | B11: Take the Week 4 quiz (quiz.md), pass with 8/10; record the score in Notes. | C11: ☐ Not started
A12: Milestone | B12: Update the Excel tracker; commit model card v2. | C12: ☐ Not started
A13: Week completion | B13: =COUNTIF(C6:C12,"✅ Done")/7 -> 0 | C13: =REPT("█",ROUND(B13*20,0))&REPT("░",20-ROUND(B13*20,0)) -> ░░░░░░░░░░░░░░░░░░░░ | E13: Deliverables: PyTorch MLP training notebook with learning curves · Neural vs baseline comparison on the test set · Error analysis note: biggest error cluster + hypothesis

Sheet Week 05
A1: Week 05, How LLMs Work: Tokens to Transformers
A2: Section: LLM Core · Category: LLM Internals · ZoroLogistics case study
A3: 🎯 Use case: Shipment-note token cost estimator plus embedding similarity search over commodity descriptions.
A5: Day | B5: Task | C5: Status | D5: Notes
A6: Mon | B6: Study tokenization and embeddings (knowledge-base 03). | C6: ☐ Not started
A7: Tue | B7: Tokenizer lab: BPE encode/decode and a token-cost estimator for the LLM API. | C7: ☐ Not started
A8: Wed | B8: Embeddings lab: similarity search over shipment commodity descriptions. | C8: ☐ Not started
A9: Thu | B9: Attention lab: implement scaled dot-product attention in NumPy; visualize the weights. | C9: ☐ Not started
A10: Fri | B10: Use case: build the context-window budget calculator (tokens per call vs window size). | C10: ☐ Not started
A11: Sat | B11: Take the Week 5 quiz (quiz.md), pass with 8/10; record the score in Notes. | C11: ☐ Not started
A12: Milestone | B12: Update the Excel tracker; commit both labs. | C12: ☐ Not started
A13: Week completion | B13: =COUNTIF(C6:C12,"✅ Done")/7 -> 0 | C13: =REPT("█",ROUND(B13*20,0))&REPT("░",20-ROUND(B13*20,0)) -> ░░░░░░░░░░░░░░░░░░░░ | E13: Deliverables: Tokenizer lab with cost estimator · Embedding similarity search over commodities · Context-window budget calculator

Sheet Week 06
A1: Week 06, Prompt Engineering & the Context Window
A2: Section: LLM Core · Category: Prompt & Context · ZoroLogistics case study
A3: 🎯 Use case: Extract bill-of-lading fields reliably with a prompt suite and per-field accuracy eval.
A5: Day | B5: Task | C5: Status | D5: Notes
A6: Mon | B6: Study prompt engineering and context engineering (knowledge-base 04). | C6: ☐ Not started
A7: Tue | B7: Build the BoL extraction prompt suite; run it against 20 synthetic documents. | C7: ☐ Not started
A8: Wed | B8: Add structured outputs and few-shot examples; improve per-field accuracy. | C8: ☐ Not started
A9: Thu | B9: Context engineering: budgets, compaction, caching. Measure tokens and latency. | C9: ☐ Not started
A10: Fri | B10: Use case: reach 90%+ field accuracy on the eval set; document the failure cases. | C10: ☐ Not started
A11: Sat | B11: Take the Week 6 quiz (quiz.md), pass with 8/10; record the score in Notes. | C11: ☐ Not started
A12: Milestone | B12: Update the Excel tracker; commit the prompt suite and eval results. | C12: ☐ Not started
A13: Week completion | B13: =COUNTIF(C6:C12,"✅ Done")/7 -> 0 | C13: =REPT("█",ROUND(B13*20,0))&REPT("░",20-ROUND(B13*20,0)) -> ░░░░░░░░░░░░░░░░░░░░ | E13: Deliverables: BoL extraction prompt suite + eval results · Structured-output pipeline · Context engineering measurements (tokens, latency, cache hits)

Sheet Week 07
A1: Week 07, RAG, Vector Search & Knowledge Graphs
A2: Section: LLM Core · Category: Retrieval & Graphs · ZoroLogistics case study
A3: 🎯 Use case: A shipping-policy Q&A bot (RAG with citations) plus a carrier-lane-port knowledge graph.
A5: Day | B5: Task | C5: Status | D5: Notes
A6: Mon | B6: Study retrieval fundamentals (knowledge-base 05). | C6: ☐ Not started
A7: Tue | B7: Chunk and embed the policy corpus; build a vector index; measure baseline retrieval accuracy. | C7: ☐ Not started
A8: Wed | B8: Add hybrid search and reranking; cite sources in answers; measure groundedness. | C8: ☐ Not started
A9: Thu | B9: Build the carrier-lane-port graph in Neo4j; query shortest and cheapest routes. | C9: ☐ Not started
A10: Fri | B10: Use case: the RAG bot answers 10 unseen questions with citations; log retrieval misses. | C10: ☐ Not started
A11: Sat | B11: Take the Week 7 quiz (quiz.md), pass with 8/10; record the score in Notes. | C11: ☐ Not started
A12: Milestone | B12: Update the Excel tracker; commit RAG and graph labs. | C12: ☐ Not started
A13: Week completion | B13: =COUNTIF(C6:C12,"✅ Done")/7 -> 0 | C13: =REPT("█",ROUND(B13*20,0))&REPT("░",20-ROUND(B13*20,0)) -> ░░░░░░░░░░░░░░░░░░░░ | E13: Deliverables: RAG policy bot with citations · Retrieval accuracy and groundedness measurements · Carrier-lane-port graph with route queries

Sheet Week 08
A1: Week 08, Open Models & Local Inference: GPUs, Ollama, llama.cpp
A2: Section: LLM Core · Category: Local Models & GPUs · ZoroLogistics case study
A3: 🎯 Use case: Run a local model to triage support tickets offline, plus a VRAM sizing calculator for model choice.
A5: Day | B5: Task | C5: Status | D5: Notes
A6: Mon | B6: Study the model landscape: open vs closed, licenses, families (knowledge-base 08). | C6: ☐ Not started
A7: Tue | B7: Install Ollama; pull a small model; run chat and structured outputs locally. | C7: ☐ Not started
A8: Wed | B8: Try llama.cpp and MLX; compare tokens/sec across backends in a table. | C8: ☐ Not started
A9: Thu | B9: GPU setup check: CUDA/MPS/ROCm; benchmark with a small script. | C9: ☐ Not started
A10: Fri | B10: Use case: ticket triage with a local model + the VRAM-based model picker. | C10: ☐ Not started
A11: Sat | B11: Take the Week 8 quiz (quiz.md), pass with 8/10; record the score in Notes. | C11: ☐ Not started
A12: Milestone | B12: Update the Excel tracker; commit the benchmark table and picker. | C12: ☐ Not started
A13: Week completion | B13: =COUNTIF(C6:C12,"✅ Done")/7 -> 0 | C13: =REPT("█",ROUND(B13*20,0))&REPT("░",20-ROUND(B13*20,0)) -> ░░░░░░░░░░░░░░░░░░░░ | E13: Deliverables: Local model playground notebook · Backend benchmark table (tokens/sec) · VRAM-based model picker

Sheet Week 09
A1: Week 09, Quantization & Efficient Inference
A2: Section: Model Engineering · Category: Quantization & Serving · ZoroLogistics case study
A3: 🎯 Use case: Quantize the triage model, serve it with vLLM, and publish a quality-vs-speed report.
A5: Day | B5: Task | C5: Status | D5: Notes
A6: Mon | B6: Study numeric formats and quantization methods (knowledge-base 06). | C6: ☐ Not started
A7: Tue | B7: Quantize a 7B or 8B model with bitsandbytes; measure quality on the triage eval. | C7: ☐ Not started
A8: Wed | B8: GGUF sweep with llama.cpp: Q4/Q5/Q8; record perplexity and speed. | C8: ☐ Not started
A9: Thu | B9: Serve with vLLM (OpenAI-compatible API); benchmark latency and throughput. | C9: ☐ Not started
A10: Fri | B10: Use case: publish the quality-vs-cost report; pick the production quantization. | C10: ☐ Not started
A11: Sat | B11: Take the Week 9 quiz (quiz.md), pass with 8/10; record the score in Notes. | C11: ☐ Not started
A12: Milestone | B12: Update the Excel tracker; commit the report. | C12: ☐ Not started
A13: Week completion | B13: =COUNTIF(C6:C12,"✅ Done")/7 -> 0 | C13: =REPT("█",ROUND(B13*20,0))&REPT("░",20-ROUND(B13*20,0)) -> ░░░░░░░░░░░░░░░░░░░░ | E13: Deliverables: Quantization sweep with quality measurements · vLLM serving + benchmark notebook · Quality-vs-cost report with a production recommendation

Sheet Week 10
A1: Week 10, Fine-Tuning: LoRA, SFT & DPO
A2: Section: Model Engineering · Category: Fine-tuning · ZoroLogistics case study
A3: 🎯 Use case: Fine-tune a small open model on ZoroLogistics support tone and bill-of-lading entity extraction.
A5: Day | B5: Task | C5: Status | D5: Notes
A6: Mon | B6: Study fine-tuning theory and the selection order (knowledge-base 06). | C6: ☐ Not started
A7: Tue | B7: Build the SFT dataset (instructions + responses) from the Week 6 corpus. | C7: ☐ Not started
A8: Wed | B8: Train LoRA with TRL/Unsloth (Colab free tier or local GPU); log loss curves. | C8: ☐ Not started
A9: Thu | B9: Create preference pairs; run a small DPO step; compare before/after on the eval. | C9: ☐ Not started
A10: Fri | B10: Use case: publish the before/after eval table; decide deploy vs iterate. | C10: ☐ Not started
A11: Sat | B11: Take the Week 10 quiz (quiz.md), pass with 8/10; record the score in Notes. | C11: ☐ Not started
A12: Milestone | B12: Update the Excel tracker; commit the adapter and eval results. | C12: ☐ Not started
A13: Week completion | B13: =COUNTIF(C6:C12,"✅ Done")/7 -> 0 | C13: =REPT("█",ROUND(B13*20,0))&REPT("░",20-ROUND(B13*20,0)) -> ░░░░░░░░░░░░░░░░░░░░ | E13: Deliverables: SFT dataset built from the Week 6 corpus · LoRA adapter + training logs · Before/after eval table and a deploy/no-deploy decision

Sheet Week 11
A1: Week 11, Evals & Error Analysis for AI Systems
A2: Section: Model Engineering · Category: Evaluation · ZoroLogistics case study
A3: 🎯 Use case: Build ZoroEval, the reusable eval harness that gates every ZoroLogistics AI artifact.
A5: Day | B5: Task | C5: Status | D5: Notes
A6: Mon | B6: Study evals and error analysis (knowledge-base 07 + Ng's letters). | C6: ☐ Not started
A7: Tue | B7: Define golden eval sets for extraction, RAG, and triage; implement LLM-as-judge with a rubric. | C7: ☐ Not started
A8: Wed | B8: Run the judges; measure judge agreement; calibrate the rubric. | C8: ☐ Not started
A9: Thu | B9: Error analysis: cluster failures from Weeks 6 to 10 artifacts; pick the top fix. | C9: ☐ Not started
A10: Fri | B10: Use case: ZoroEval v1 gates one artifact in a CI-style script; document the loop. | C10: ☐ Not started
A11: Sat | B11: Take the Week 11 quiz (quiz.md), pass with 8/10; record the score in Notes. | C11: ☐ Not started
A12: Milestone | B12: Update the Excel tracker; commit ZoroEval. | C12: ☐ Not started
A13: Week completion | B13: =COUNTIF(C6:C12,"✅ Done")/7 -> 0 | C13: =REPT("█",ROUND(B13*20,0))&REPT("░",20-ROUND(B13*20,0)) -> ░░░░░░░░░░░░░░░░░░░░ | E13: Deliverables: Golden eval sets for extraction, RAG, and triage · LLM-as-judge with a calibrated rubric · ZoroEval harness + CI-style gate script

Sheet Week 12
A1: Week 12, Coding-Agent Harnesses: Claude Code, Cursor, OpenCode, DSH
A2: Section: Harnesses & Loops · Category: Harnesses · ZoroLogistics case study
A3: 🎯 Use case: Build the ZoroLogistics ETA CLI (query tool) entirely with a coding agent from a written spec.
A5: Day | B5: Task | C5: Status | D5: Notes
A6: Mon | B6: Install and authenticate 2 harnesses (Claude Code + OpenCode or DSH); read the skill guides. | C6: ☐ Not started
A7: Tue | B7: Write SPEC.md for the ETA CLI: user, constraints, one refused tradeoff, test plan. | C7: ☐ Not started
A8: Wed | B8: Drive the agent to build the CLI; run the tests; iterate until green. | C8: ☐ Not started
A9: Thu | B9: Repeat the same task in a second harness; compare plans, cost, and code quality. | C9: ☐ Not started
A10: Fri | B10: Use case: ship the CLI; write the 1-page harness comparison for your team. | C10: ☐ Not started
A11: Sat | B11: Take the Week 12 quiz (quiz.md), pass with 8/10; record the score in Notes. | C11: ☐ Not started
A12: Milestone | B12: Update the Excel tracker; commit the CLI and comparison. | C12: ☐ Not started
A13: Week completion | B13: =COUNTIF(C6:C12,"✅ Done")/7 -> 0 | C13: =REPT("█",ROUND(B13*20,0))&REPT("░",20-ROUND(B13*20,0)) -> ░░░░░░░░░░░░░░░░░░░░ | E13: Deliverables: ETA CLI built agentically, with tests green · Harness setup + comparison notebook · 1-page harness comparison write-up

Sheet Week 13
A1: Week 13, Agentic Coding Loops & Spec-Driven Development
A2: Section: Harnesses & Loops · Category: Loops & Specs · ZoroLogistics case study
A3: 🎯 Use case: Ship the ZoroLogistics Support Bot MVP through the full three-loop cycle with evals closing every loop.
A5: Day | B5: Task | C5: Status | D5: Notes
A6: Mon | B6: Study the three loops and verifier patterns (knowledge-base 01). | C6: ☐ Not started
A7: Tue | B7: Spec the support bot MVP; define the verifier (eval suite + unit tests). | C7: ☐ Not started
A8: Wed | B8: Agentic loop session: build → test → fix until the verifier passes; log the loop. | C8: ☐ Not started
A9: Thu | B9: Developer loop: review with fresh eyes, update the spec, add missed edge cases. | C9: ☐ Not started
A10: Fri | B10: Use case: external loop. Have someone real use the bot; file issues; update spec + evals. | C10: ☐ Not started
A11: Sat | B11: Take the Week 13 quiz (quiz.md), pass with 8/10; record the score in Notes. | C11: ☐ Not started
A12: Milestone | B12: Update the Excel tracker; commit the MVP and loop log. | C12: ☐ Not started
A13: Week completion | B13: =COUNTIF(C6:C12,"✅ Done")/7 -> 0 | C13: =REPT("█",ROUND(B13*20,0))&REPT("░",20-ROUND(B13*20,0)) -> ░░░░░░░░░░░░░░░░░░░░ | E13: Deliverables: Support bot MVP with a green verifier (unit tests + eval) · Loop log (agentic/developer/external cycles) · Spec updates driven by feedback

Sheet Week 14
A1: Week 14, Agent Fundamentals: The Loop, Tools & Memory
A2: Section: Agents · Category: Agent Core · ZoroLogistics case study
A3: 🎯 Use case: Build the shipment-tracking agent from scratch: lookup, calculator, and web tools.
A5: Day | B5: Task | C5: Status | D5: Notes
A6: Mon | B6: Study the agent loop and ReAct (knowledge-base 10). | C6: ☐ Not started
A7: Tue | B7: Implement the tool-calling loop by hand; wire 2 tools (track shipment, convert units). | C7: ☐ Not started
A8: Wed | B8: Add planning and reflection; log every step: the trace is your debugger. | C8: ☐ Not started
A9: Thu | B9: Add guardrails: refusal, max steps, cost cap; test adversarial inputs. | C9: ☐ Not started
A10: Fri | B10: Use case: the agent solves 10 unseen scenarios; publish the trace log. | C10: ☐ Not started
A11: Sat | B11: Take the Week 14 quiz (quiz.md), pass with 8/10; record the score in Notes. | C11: ☐ Not started
A12: Milestone | B12: Update the Excel tracker; commit the agent and traces. | C12: ☐ Not started
A13: Week completion | B13: =COUNTIF(C6:C12,"✅ Done")/7 -> 0 | C13: =REPT("█",ROUND(B13*20,0))&REPT("░",20-ROUND(B13*20,0)) -> ░░░░░░░░░░░░░░░░░░░░ | E13: Deliverables: Hand-written agent with 3+ tools · Trace log of every run · Guardrail tests (refusal, max steps, cost cap)

Sheet Week 15
A1: Week 15, Agent Frameworks: LangGraph & the State-Graph Model
A2: Section: Agents · Category: Frameworks · ZoroLogistics case study
A3: 🎯 Use case: Re-implement the support agent in LangGraph with a human approval step for refunds.
A5: Day | B5: Task | C5: Status | D5: Notes
A6: Mon | B6: Study graph-based agent design (knowledge-base 10 + LangGraph docs). | C6: ☐ Not started
A7: Tue | B7: Port the Week 14 agent to LangGraph; visualize the graph. | C7: ☐ Not started
A8: Wed | B8: Add checkpoints and resume; crash mid-run and recover. | C8: ☐ Not started
A9: Thu | B9: Add the human-in-the-loop interrupt for refunds over $500. | C9: ☐ Not started
A10: Fri | B10: Use case: end-to-end run with approval; record latency and tokens per node. | C10: ☐ Not started
A11: Sat | B11: Take the Week 15 quiz (quiz.md), pass with 8/10; record the score in Notes. | C11: ☐ Not started
A12: Milestone | B12: Update the Excel tracker; commit the graph agent. | C12: ☐ Not started
A13: Week completion | B13: =COUNTIF(C6:C12,"✅ Done")/7 -> 0 | C13: =REPT("█",ROUND(B13*20,0))&REPT("░",20-ROUND(B13*20,0)) -> ░░░░░░░░░░░░░░░░░░░░ | E13: Deliverables: LangGraph support agent with visualized graph · Checkpoint/resume demonstration · Human-in-the-loop refund approval flow

Sheet Week 16
A1: Week 16, Multi-Agent Systems & MCP
A2: Section: Agents · Category: Multi-Agent & Protocols · ZoroLogistics case study
A3: 🎯 Use case: A support triage team: router + specialists (tracking, refunds, docs) over MCP tools.
A5: Day | B5: Task | C5: Status | D5: Notes
A6: Mon | B6: Study orchestration patterns and MCP (knowledge-base 10/11). | C6: ☐ Not started
A7: Tue | B7: Build an MCP server exposing ZoroLogistics tools; test with an MCP inspector. | C7: ☐ Not started
A8: Wed | B8: Build the multi-agent triage team (supervisor + 3 specialists). | C8: ☐ Not started
A9: Thu | B9: A/B test: multi-agent vs single agent on the same 10 tasks; measure quality and cost. | C9: ☐ Not started
A10: Fri | B10: Use case: publish the A/B report; justify your architecture decision. | C10: ☐ Not started
A11: Sat | B11: Take the Week 16 quiz (quiz.md), pass with 8/10; record the score in Notes. | C11: ☐ Not started
A12: Milestone | B12: Update the Excel tracker; commit the team and the MCP server. | C12: ☐ Not started
A13: Week completion | B13: =COUNTIF(C6:C12,"✅ Done")/7 -> 0 | C13: =REPT("█",ROUND(B13*20,0))&REPT("░",20-ROUND(B13*20,0)) -> ░░░░░░░░░░░░░░░░░░░░ | E13: Deliverables: MCP server exposing ZoroLogistics tools · Multi-agent triage team · A/B report: multi-agent vs single agent

Sheet Week 17
A1: Week 17, OpenClaw, Hermes & Agent Operations
A2: Section: Agents · Category: Personal Agents & Ops · ZoroLogistics case study
A3: 🎯 Use case: Deploy a personal ZoroLab assistant (OpenClaw) wired to your MCP server, driven by a Hermes-class model.
A5: Day | B5: Task | C5: Status | D5: Notes
A6: Mon | B6: Study OpenClaw and Hermes (reference/agents/ guides + knowledge-base 10). | C6: ☐ Not started
A7: Tue | B7: Install and configure OpenClaw locally; connect a channel (WebChat or Telegram). | C7: ☐ Not started
A8: Wed | B8: Write 2 OpenClaw skills; wire the Week 16 MCP server; test the context loop. | C8: ☐ Not started
A9: Thu | B9: Swap in a Hermes-class model via Ollama; compare assistant quality. | C9: ☐ Not started
A10: Fri | B10: Use case: add tracing and cost tracking to the assistant; publish the ops runbook. | C10: ☐ Not started
A11: Sat | B11: Take the Week 17 quiz (quiz.md), pass with 8/10; record the score in Notes. | C11: ☐ Not started
A12: Milestone | B12: Update the Excel tracker; commit skills and the runbook. | C12: ☐ Not started
A13: Week completion | B13: =COUNTIF(C6:C12,"✅ Done")/7 -> 0 | C13: =REPT("█",ROUND(B13*20,0))&REPT("░",20-ROUND(B13*20,0)) -> ░░░░░░░░░░░░░░░░░░░░ | E13: Deliverables: Working OpenClaw installation with 2 custom skills · MCP integration with the Week 16 server · Agent ops runbook (tracing + cost)

Sheet Week 18
A1: Week 18, Azure AI Foundry
A2: Section: Cloud AI Platforms · Category: Microsoft · ZoroLogistics case study
A3: 🎯 Use case: Deploy the support agent to Foundry with online evaluation and gateway rate limits.
A5: Day | B5: Task | C5: Status | D5: Notes
A6: Mon | B6: Set up the Azure subscription and AI Foundry hub/project (free tier). | C6: ☐ Not started
A7: Tue | B7: Deploy a serverless model endpoint; call it from the Python SDK and OpenAI SDK. | C7: ☐ Not started
A8: Wed | B8: Create the support agent in Foundry with tools; test in the playground. | C8: ☐ Not started
A9: Thu | B9: Run an online evaluation batch; read the trace; fix the worst failure. | C9: ☐ Not started
A10: Fri | B10: Use case: put the agent behind the AI Gateway (rate limit + content safety); publish cost. | C10: ☐ Not started
A11: Sat | B11: Take the Week 18 quiz (quiz.md), pass with 8/10; record the score in Notes. | C11: ☐ Not started
A12: Milestone | B12: Update the Excel tracker; commit the Foundry deployment guide. | C12: ☐ Not started
A13: Week completion | B13: =COUNTIF(C6:C12,"✅ Done")/7 -> 0 | C13: =REPT("█",ROUND(B13*20,0))&REPT("░",20-ROUND(B13*20,0)) -> ░░░░░░░░░░░░░░░░░░░░ | E13: Deliverables: Serverless endpoint callable from Python · Foundry agent with tools + evaluation trace · Gateway-governed endpoint with documented cost

Sheet Week 19
A1: Week 19, Google Vertex AI & Gemini
A2: Section: Cloud AI Platforms · Category: Google · ZoroLogistics case study
A3: 🎯 Use case: A multimodal bill-of-lading pipeline: Gemini OCR → structured JSON → BigQuery table.
A5: Day | B5: Task | C5: Status | D5: Notes
A6: Mon | B6: Set up Google Cloud and AI Studio; get an API key; check quotas. | C6: ☐ Not started
A7: Tue | B7: Gemini multimodal lab: BoL images → structured JSON; measure accuracy. | C7: ☐ Not started
A8: Wed | B8: Recreate the support agent with ADK/Agent Engine; compare with the Foundry version. | C8: ☐ Not started
A9: Thu | B9: Run a Vertex evaluation on a golden set; log results to BigQuery. | C9: ☐ Not started
A10: Fri | B10: Use case: end-to-end pipeline (images → clean table); publish cost per document. | C10: ☐ Not started
A11: Sat | B11: Take the Week 19 quiz (quiz.md), pass with 8/10; record the score in Notes. | C11: ☐ Not started
A12: Milestone | B12: Update the Excel tracker; commit the Vertex guide. | C12: ☐ Not started
A13: Week completion | B13: =COUNTIF(C6:C12,"✅ Done")/7 -> 0 | C13: =REPT("█",ROUND(B13*20,0))&REPT("░",20-ROUND(B13*20,0)) -> ░░░░░░░░░░░░░░░░░░░░ | E13: Deliverables: Multimodal OCR notebook with accuracy measurement · Support agent rebuilt with ADK/Agent Engine · End-to-end pipeline with cost per document

Sheet Week 20
A1: Week 20, AWS Bedrock & SageMaker AI
A2: Section: Cloud AI Platforms · Category: AWS · ZoroLogistics case study
A3: 🎯 Use case: A Bedrock RAG support agent with Guardrails, plus the Great Platform Comparison matrix.
A5: Day | B5: Task | C5: Status | D5: Notes
A6: Mon | B6: Set up the AWS account and IAM least-privilege role; enable Bedrock models. | C6: ☐ Not started
A7: Tue | B7: Converse API lab: run the Week 6 prompt suite across Bedrock models. | C7: ☐ Not started
A8: Wed | B8: Build a Knowledge Base (RAG) for shipping policies; query with citations. | C8: ☐ Not started
A9: Thu | B9: Create a Bedrock Agent + Guardrails; test blocked prompts. | C9: ☐ Not started
A10: Fri | B10: Use case: publish the 3-cloud comparison matrix (Foundry vs Vertex vs Bedrock) with cost. | C10: ☐ Not started
A11: Sat | B11: Take the Week 20 quiz (quiz.md), pass with 8/10; record the score in Notes. | C11: ☐ Not started
A12: Milestone | B12: Update the Excel tracker; commit the AWS guide and matrix. | C12: ☐ Not started
A13: Week completion | B13: =COUNTIF(C6:C12,"✅ Done")/7 -> 0 | C13: =REPT("█",ROUND(B13*20,0))&REPT("░",20-ROUND(B13*20,0)) -> ░░░░░░░░░░░░░░░░░░░░ | E13: Deliverables: Converse API prompt-suite run across Bedrock models · Knowledge Base RAG with citations · Bedrock Agent + Guardrails; three-cloud comparison matrix

Sheet Week 21
A1: Week 21, Databricks Day Zero: Unity Catalog & the Lakehouse
A2: Section: Databricks Zero to Hero · Category: Platform & Data · ZoroLogistics case study
A3: 🎯 Use case: Stand up the ZoroLogistics lakehouse: bronze → silver → gold entirely in SQL.
A5: Day | B5: Task | C5: Status | D5: Notes
A6: Mon | B6: Create the Databricks account/workspace (free trial); tour the UI. | C6: ☐ Not started
A7: Tue | B7: Unity Catalog lab: create catalog/schema/volume; load CSV data; grant rights. | C7: ☐ Not started
A8: Wed | B8: Delta Lake lab: create tables, time travel, VACUUM, OPTIMIZE, liquid clustering. | C8: ☐ Not started
A9: Thu | B9: Medallion in SQL: bronze raw → silver clean → gold aggregates for shipments. | C9: ☐ Not started
A10: Fri | B10: Use case: governed silver/gold tables with lineage; build a first AI/BI dashboard. | C10: ☐ Not started
A11: Sat | B11: Take the Week 21 quiz (quiz.md), pass with 8/10; record the score in Notes. | C11: ☐ Not started
A12: Milestone | B12: Update the Excel tracker; commit the SQL notebooks. | C12: ☐ Not started
A13: Week completion | B13: =COUNTIF(C6:C12,"✅ Done")/7 -> 0 | C13: =REPT("█",ROUND(B13*20,0))&REPT("░",20-ROUND(B13*20,0)) -> ░░░░░░░░░░░░░░░░░░░░ | E13: Deliverables: Unity Catalog catalog/schema/volume with grants · Delta tables with time-travel demo · Silver/gold medallion tables + first AI/BI dashboard

Sheet Week 22
A1: Week 22, Databricks Data Engineering: PySpark, Streaming & Lakeflow
A2: Section: Databricks Zero to Hero · Category: Pipelines · ZoroLogistics case study
A3: 🎯 Use case: A streaming pipeline: live shipment events → validated silver → on-time KPIs.
A5: Day | B5: Task | C5: Status | D5: Notes
A6: Mon | B6: PySpark lab: transform shipment data with DataFrames; compare with SQL. | C6: ☐ Not started
A7: Tue | B7: Write a DLT pipeline in Python (or SQL) with expectations on data quality. | C7: ☐ Not started
A8: Wed | B8: Add a streaming table for live shipment events (Auto Loader/streaming source). | C8: ☐ Not started
A9: Thu | B9: Create a Lakeflow Job: schedule and orchestrate the pipeline; check runs and lineage. | C9: ☐ Not started
A10: Fri | B10: Use case: the streaming KPI pipeline passes quality gates; publish a monitoring query. | C10: ☐ Not started
A11: Sat | B11: Take the Week 22 quiz (quiz.md), pass with 8/10; record the score in Notes. | C11: ☐ Not started
A12: Milestone | B12: Update the Excel tracker; commit the pipeline code. | C12: ☐ Not started
A13: Week completion | B13: =COUNTIF(C6:C12,"✅ Done")/7 -> 0 | C13: =REPT("█",ROUND(B13*20,0))&REPT("░",20-ROUND(B13*20,0)) -> ░░░░░░░░░░░░░░░░░░░░ | E13: Deliverables: PySpark transformation notebook · DLT pipeline with expectations (data quality gates) · Scheduled Lakeflow Job + monitoring query

Sheet Week 23
A1: Week 23, Databricks ML & GenAI: Training, Serving, Genie
A2: Section: Databricks Zero to Hero · Category: ML & GenAI · ZoroLogistics case study
A3: 🎯 Use case: A point-in-time ETA model + RAG over shipping docs + a Genie space for ops analysts.
A5: Day | B5: Task | C5: Status | D5: Notes
A6: Mon | B6: MLflow + feature tables: log a baseline; build point-in-time features. | C6: ☐ Not started
A7: Tue | B7: Train the ETA model (XGBoost or PyTorch); register it in MLflow; compare challenger. | C7: ☐ Not started
A8: Wed | B8: Create the serving endpoint + AI Gateway rate limit; call from Python. | C8: ☐ Not started
A9: Thu | B9: Vector Search: index policy docs; build the RAG chain with ai_query. | C9: ☐ Not started
A10: Fri | B10: Use case: Genie space on the gold tables; verify its SQL; publish it. | C10: ☐ Not started
A11: Sat | B11: Take the Week 23 quiz (quiz.md), pass with 8/10; record the score in Notes. | C11: ☐ Not started
A12: Milestone | B12: Update the Excel tracker; commit the ML assets. | C12: ☐ Not started
A13: Week completion | B13: =COUNTIF(C6:C12,"✅ Done")/7 -> 0 | C13: =REPT("█",ROUND(B13*20,0))&REPT("░",20-ROUND(B13*20,0)) -> ░░░░░░░░░░░░░░░░░░░░ | E13: Deliverables: Registered ETA model with point-in-time features · Serving endpoint behind the AI Gateway · Vector Search RAG + Genie space with verified answers

Sheet Week 24
A1: Week 24, Databricks Production: DABs, Governance & the Capstone
A2: Section: Databricks Zero to Hero · Category: Production & Capstone · ZoroLogistics case study
A3: 🎯 Use case: Capstone: ZoroLogistics Lakehouse Intelligence, deploying the entire Weeks 21 to 23 stack via DABs.
A5: Day | B5: Task | C5: Status | D5: Notes
A6: Mon | B6: Bundle the Weeks 22 to 23 assets into a DAB; validate and deploy with the CLI. | C6: ☐ Not started
A7: Tue | B7: Add CI/CD: GitHub Actions validates and deploys the bundle. | C7: ☐ Not started
A8: Wed | B8: Governance: row filters + column masks + lineage review; write an audit query. | C8: ☐ Not started
A9: Thu | B9: FinOps: billing system-table dashboard; find one cost win; document it. | C9: ☐ Not started
A10: Fri | B10: Use case: capstone demo end-to-end + graduation checklist; publish your portfolio. | C10: ☐ Not started
A11: Sat | B11: Take the Week 24 quiz (quiz.md), pass with 8/10; record the score in Notes. | C11: ☐ Not started
A12: Milestone | B12: Update the Excel tracker: Week 24 done, program complete. | C12: ☐ Not started
A13: Week completion | B13: =COUNTIF(C6:C12,"✅ Done")/7 -> 0 | C13: =REPT("█",ROUND(B13*20,0))&REPT("░",20-ROUND(B13*20,0)) -> ░░░░░░░░░░░░░░░░░░░░ | E13: Deliverables: DAB deployable end-to-end (pipeline + model + dashboard) · CI/CD workflow that validates and deploys · Governance + FinOps write-up; graduation checklist

Sheet About
A1: AI Engineering Lab, Progress Tracker
A2: How to use this workbook
A4: 1. Fill in your name and start date on the Dashboard sheet.
A5: 2. Each week has its own sheet (Week 01 … Week 24) with the week's checklist:
A6: study, notebook, and use-case tasks, one line per program day.
A7: 3. Set a task's Status cell (dropdown) to ✅ Done when you finish it. The week's
A8: completion % and the in-cell progress bar update automatically.
A9: 4. The Dashboard aggregates every week: status, % bars, phase averages, and a
A10: progress chart. Tick all six tasks in a week to mark it ✅ Complete.
A12: Statuses
A13: ☐ Not started · ▶ In progress · ✅ Done · ⏭ Skipped
A14: Skipped tasks count against the week %, use Notes to say why.
... A20: © 2026 Zorost Intelligence LLC · https://zorost.com
